2024-08-03 07:48:42,752: INFO: /Users/zmakhkha/Desktop/promote-me/back/usrinfo/auth.py changed, reloading.
2024-08-03 07:48:55,469: INFO: /Users/zmakhkha/Desktop/promote-me/back/usrinfo/auth.py changed, reloading.
2024-08-03 07:49:16,304: INFO: /Users/zmakhkha/Desktop/promote-me/back/usrinfo/auth.py changed, reloading.
2024-08-03 07:49:21,874: INFO: /Users/zmakhkha/Desktop/promote-me/back/usrinfo/auth.py changed, reloading.
2024-08-03 07:49:24,421: INFO: /Users/zmakhkha/Desktop/promote-me/back/usrinfo/auth.py changed, reloading.
2024-08-03 07:49:43,749: WARNING: Not Found: /auth/signin/
2024-08-03 07:49:55,238: WARNING: Method Not Allowed: /auth/signIn/
2024-08-03 07:54:08,833: CRITICAL: [AuthViewSet::signIn] Invalid login attempt for email ads@lala.com
2024-08-03 07:54:08,834: WARNING: Unauthorized: /auth/signIn/
2024-08-03 07:54:41,388: WARNING: Not Found: /auth/user/
2024-08-03 07:54:41,390: WARNING: Not Found: /auth/user/
2024-08-03 07:57:04,928: WARNING: Bad Request: /auth/signUp/
2024-08-03 07:57:53,031: WARNING: Bad Request: /auth/signUp/
2024-08-03 07:58:40,081: INFO: [AuthViewSet::signIn] User lexi@mail.com logged in successfully
2024-08-03 08:06:31,295: WARNING: Not Found: /auth/user/
2024-08-03 08:06:31,302: WARNING: Not Found: /auth/user/
2024-08-03 08:06:49,348: WARNING: Not Found: /auth/user/
2024-08-03 08:09:57,469: WARNING: Not Found: /auth/user/
2024-08-03 08:09:59,226: WARNING: Not Found: /auth/user/
2024-08-03 08:10:07,595: WARNING: Not Found: /auth/user/
2024-08-03 08:10:12,611: WARNING: Not Found: /auth/user/
2024-08-03 08:10:17,618: WARNING: Not Found: /auth/user/
2024-08-03 08:10:27,466: WARNING: Not Found: /auth/user/
2024-08-03 08:20:09,472: WARNING: Not Found: /auth/user/
2024-08-03 08:20:10,109: WARNING: Not Found: /auth/user/
2024-08-03 08:20:10,261: WARNING: Not Found: /auth/user/
2024-08-03 08:20:10,821: WARNING: Not Found: /auth/user/
2024-08-03 08:20:10,989: WARNING: Not Found: /auth/user/
2024-08-03 08:20:11,158: WARNING: Not Found: /auth/user/
2024-08-03 08:20:11,302: WARNING: Not Found: /auth/user/
2024-08-03 08:20:11,454: WARNING: Not Found: /auth/user/
2024-08-03 08:20:12,237: WARNING: Not Found: /auth/user/
2024-08-03 08:20:12,718: WARNING: Not Found: /auth/user/
2024-08-03 08:20:12,885: WARNING: Not Found: /auth/user/
2024-08-03 08:20:13,053: WARNING: Not Found: /auth/user/
2024-08-03 08:20:14,676: WARNING: Not Found: /auth/user/
2024-08-03 08:20:15,126: WARNING: Not Found: /auth/user/
2024-08-03 08:20:15,285: WARNING: Not Found: /auth/user/
2024-08-03 08:20:18,693: WARNING: Not Found: /auth/user/
2024-08-03 08:20:19,094: WARNING: Not Found: /auth/user/
2024-08-03 08:20:19,429: WARNING: Not Found: /auth/user/
2024-08-03 08:20:20,092: WARNING: Not Found: /auth/user/
2024-08-03 08:20:20,317: WARNING: Not Found: /auth/user/
2024-08-03 08:20:25,453: WARNING: Not Found: /auth/user/
2024-08-03 08:20:25,901: WARNING: Not Found: /auth/user/
2024-08-03 08:20:26,037: WARNING: Not Found: /auth/user/
2024-08-03 08:20:28,035: WARNING: Not Found: /auth/user/
2024-08-03 08:20:28,041: WARNING: Not Found: /auth/user/
2024-08-03 08:20:29,325: WARNING: Not Found: /auth/user/
2024-08-03 08:20:30,014: WARNING: Not Found: /auth/user/
2024-08-03 08:20:30,212: WARNING: Not Found: /auth/user/
2024-08-03 08:20:30,356: WARNING: Not Found: /auth/user/
2024-08-03 08:20:41,466: WARNING: Not Found: /auth/user/
2024-08-03 08:20:41,472: WARNING: Not Found: /auth/user/
2024-08-03 08:24:27,629: INFO: /Users/zmakhkha/Desktop/promote-me/back/usrinfo/models.py changed, reloading.
2024-08-03 08:26:05,335: INFO: /Users/zmakhkha/Desktop/promote-me/back/usrinfo/models.py changed, reloading.
2024-08-03 08:26:08,909: INFO: /Users/zmakhkha/Desktop/promote-me/back/usrinfo/models.py changed, reloading.
2024-08-03 08:26:30,881: INFO: /Users/zmakhkha/Desktop/promote-me/back/usrinfo/models.py changed, reloading.
2024-08-03 08:27:37,280: INFO: /Users/zmakhkha/Desktop/promote-me/back/usrinfo/models.py changed, reloading.
2024-08-03 08:31:41,272: INFO: /Users/zmakhkha/Desktop/promote-me/back/usrinfo/serializers.py changed, reloading.
2024-08-03 08:32:18,623: INFO: /Users/zmakhkha/Desktop/promote-me/back/usrinfo/serializers.py changed, reloading.
2024-08-03 08:32:21,136: INFO: /Users/zmakhkha/Desktop/promote-me/back/usrinfo/serializers.py changed, reloading.
2024-08-03 08:32:23,660: INFO: /Users/zmakhkha/Desktop/promote-me/back/usrinfo/serializers.py changed, reloading.
2024-08-03 08:42:41,020: ERROR: Internal Server Error: /admin/login/
Traceback (most recent call last):
  File "/goinfre/zmakhkha/venv/lib/python3.9/site-packages/django/core/handlers/exception.py", line 55, in inner
    response = get_response(request)
  File "/goinfre/zmakhkha/venv/lib/python3.9/site-packages/django/core/handlers/base.py", line 197, in _get_response
    response = wrapped_callback(request, *callback_args, **callback_kwargs)
  File "/goinfre/zmakhkha/venv/lib/python3.9/site-packages/django/utils/decorators.py", line 46, in _wrapper
    return bound_method(*args, **kwargs)
  File "/goinfre/zmakhkha/venv/lib/python3.9/site-packages/django/views/decorators/cache.py", line 62, in _wrapper_view_func
    response = view_func(request, *args, **kwargs)
  File "/goinfre/zmakhkha/venv/lib/python3.9/site-packages/django/contrib/admin/sites.py", line 422, in login
    **self.each_context(request),
  File "/goinfre/zmakhkha/venv/lib/python3.9/site-packages/django/contrib/admin/sites.py", line 337, in each_context
    "available_apps": self.get_app_list(request),
  File "/goinfre/zmakhkha/venv/lib/python3.9/site-packages/django/contrib/admin/sites.py", line 536, in get_app_list
    app_dict = self._build_app_dict(request, app_label)
  File "/goinfre/zmakhkha/venv/lib/python3.9/site-packages/django/contrib/admin/sites.py", line 478, in _build_app_dict
    has_module_perms = model_admin.has_module_permission(request)
  File "/goinfre/zmakhkha/venv/lib/python3.9/site-packages/django/contrib/admin/options.py", line 611, in has_module_permission
    return request.user.has_module_perms(self.opts.app_label)
  File "/goinfre/zmakhkha/venv/lib/python3.9/site-packages/django/utils/functional.py", line 268, in inner
    return func(_wrapped, *args)
AttributeError: 'AppUser' object has no attribute 'has_module_perms'
2024-08-03 08:42:41,280: WARNING: Not Found: /favicon.ico
2024-08-03 08:43:38,733: INFO: /Users/zmakhkha/Desktop/promote-me/back/usrinfo/models.py changed, reloading.
2024-08-03 08:45:49,618: INFO: /Users/zmakhkha/Desktop/promote-me/back/usrinfo/admin.py changed, reloading.
2024-08-03 08:45:57,408: INFO: /Users/zmakhkha/Desktop/promote-me/back/usrinfo/admin.py changed, reloading.
2024-08-03 08:45:58,903: INFO: /Users/zmakhkha/Desktop/promote-me/back/usrinfo/admin.py changed, reloading.
2024-08-03 08:46:02,428: INFO: /Users/zmakhkha/Desktop/promote-me/back/usrinfo/admin.py changed, reloading.
2024-08-03 08:46:12,131: INFO: /Users/zmakhkha/Desktop/promote-me/back/usrinfo/admin.py changed, reloading.
2024-08-03 08:46:17,731: INFO: /Users/zmakhkha/Desktop/promote-me/back/usrinfo/admin.py changed, reloading.
2024-08-03 08:46:44,024: INFO: /Users/zmakhkha/Desktop/promote-me/back/usrinfo/admin.py changed, reloading.
2024-08-03 08:47:29,413: INFO: /Users/zmakhkha/Desktop/promote-me/back/usrinfo/models.py changed, reloading.
2024-08-03 08:47:33,997: INFO: /Users/zmakhkha/Desktop/promote-me/back/usrinfo/models.py changed, reloading.
2024-08-03 08:47:45,691: INFO: /Users/zmakhkha/Desktop/promote-me/back/usrinfo/models.py changed, reloading.
2024-08-03 08:47:53,358: INFO: /Users/zmakhkha/Desktop/promote-me/back/usrinfo/models.py changed, reloading.
2024-08-03 08:48:12,617: INFO: /Users/zmakhkha/Desktop/promote-me/back/usrinfo/models.py changed, reloading.
2024-08-03 08:52:14,652: INFO: /Users/zmakhkha/Desktop/promote-me/back/usrinfo/urls.py changed, reloading.
2024-08-03 08:52:24,560: INFO: /Users/zmakhkha/Desktop/promote-me/back/usrinfo/urls.py changed, reloading.
2024-08-03 08:52:32,136: INFO: /Users/zmakhkha/Desktop/promote-me/back/usrinfo/urls.py changed, reloading.
2024-08-03 08:54:52,608: INFO: /Users/zmakhkha/Desktop/promote-me/back/core/urls.py changed, reloading.
2024-08-03 08:58:47,802: INFO: /Users/zmakhkha/Desktop/promote-me/back/usrinfo/serializers.py changed, reloading.
2024-08-03 08:58:57,654: INFO: /Users/zmakhkha/Desktop/promote-me/back/usrinfo/serializers.py changed, reloading.
2024-08-03 08:58:59,212: INFO: /Users/zmakhkha/Desktop/promote-me/back/usrinfo/serializers.py changed, reloading.
2024-08-03 08:59:05,811: INFO: /Users/zmakhkha/Desktop/promote-me/back/usrinfo/serializers.py changed, reloading.
2024-08-03 08:59:07,359: INFO: /Users/zmakhkha/Desktop/promote-me/back/usrinfo/serializers.py changed, reloading.
2024-08-03 09:03:14,362: INFO: /Users/zmakhkha/Desktop/promote-me/back/usrinfo/serializers.py changed, reloading.
2024-08-03 09:03:55,873: INFO: /Users/zmakhkha/Desktop/promote-me/back/usrinfo/serializers.py changed, reloading.
2024-08-03 09:06:32,462: INFO: /Users/zmakhkha/Desktop/promote-me/back/usrinfo/views.py changed, reloading.
2024-08-03 09:06:58,541: INFO: /Users/zmakhkha/Desktop/promote-me/back/usrinfo/views.py changed, reloading.
2024-08-03 09:07:30,075: INFO: /Users/zmakhkha/Desktop/promote-me/back/usrinfo/views.py changed, reloading.
2024-08-03 09:07:43,236: INFO: /Users/zmakhkha/Desktop/promote-me/back/usrinfo/views.py changed, reloading.
2024-08-03 09:07:45,747: INFO: /Users/zmakhkha/Desktop/promote-me/back/usrinfo/views.py changed, reloading.
2024-08-03 09:07:49,335: INFO: /Users/zmakhkha/Desktop/promote-me/back/usrinfo/views.py changed, reloading.
2024-08-03 09:07:51,863: INFO: /Users/zmakhkha/Desktop/promote-me/back/usrinfo/views.py changed, reloading.
2024-08-03 09:07:55,404: INFO: /Users/zmakhkha/Desktop/promote-me/back/usrinfo/views.py changed, reloading.
2024-08-03 09:08:27,555: INFO: /Users/zmakhkha/Desktop/promote-me/back/usrinfo/views.py changed, reloading.
2024-08-03 09:09:33,350: INFO: /Users/zmakhkha/Desktop/promote-me/back/usrinfo/views.py changed, reloading.
2024-08-03 09:09:37,901: INFO: /Users/zmakhkha/Desktop/promote-me/back/usrinfo/views.py changed, reloading.
2024-08-03 09:09:40,442: INFO: /Users/zmakhkha/Desktop/promote-me/back/usrinfo/views.py changed, reloading.
2024-08-03 09:10:46,196: INFO: /Users/zmakhkha/Desktop/promote-me/back/usrinfo/views.py changed, reloading.
2024-08-03 09:11:02,429: INFO: /Users/zmakhkha/Desktop/promote-me/back/usrinfo/views.py changed, reloading.
2024-08-03 09:11:45,719: INFO: /Users/zmakhkha/Desktop/promote-me/back/usrinfo/views.py changed, reloading.
2024-08-03 09:11:47,232: INFO: /Users/zmakhkha/Desktop/promote-me/back/usrinfo/views.py changed, reloading.
2024-08-03 09:11:48,758: INFO: /Users/zmakhkha/Desktop/promote-me/back/usrinfo/views.py changed, reloading.
2024-08-03 09:12:41,753: INFO: /Users/zmakhkha/Desktop/promote-me/back/usrinfo/views.py changed, reloading.
2024-08-03 09:13:09,045: INFO: /Users/zmakhkha/Desktop/promote-me/back/usrinfo/views.py changed, reloading.
2024-08-03 09:13:12,602: INFO: /Users/zmakhkha/Desktop/promote-me/back/usrinfo/views.py changed, reloading.
2024-08-03 09:13:20,236: INFO: /Users/zmakhkha/Desktop/promote-me/back/usrinfo/views.py changed, reloading.
2024-08-03 09:13:32,969: INFO: /Users/zmakhkha/Desktop/promote-me/back/usrinfo/views.py changed, reloading.
2024-08-03 09:14:08,167: INFO: /Users/zmakhkha/Desktop/promote-me/back/usrinfo/views.py changed, reloading.
2024-08-03 09:16:47,620: INFO: /Users/zmakhkha/Desktop/promote-me/back/usrinfo/views.py changed, reloading.
2024-08-03 09:16:51,185: INFO: /Users/zmakhkha/Desktop/promote-me/back/usrinfo/views.py changed, reloading.
2024-08-03 09:16:55,757: INFO: /Users/zmakhkha/Desktop/promote-me/back/usrinfo/views.py changed, reloading.
2024-08-03 09:17:16,021: INFO: /Users/zmakhkha/Desktop/promote-me/back/usrinfo/views.py changed, reloading.
2024-08-03 09:18:34,958: INFO: /Users/zmakhkha/Desktop/promote-me/back/usrinfo/views.py changed, reloading.
2024-08-03 09:18:38,726: INFO: /Users/zmakhkha/Desktop/promote-me/back/usrinfo/views.py changed, reloading.
2024-08-03 09:18:55,526: INFO: /Users/zmakhkha/Desktop/promote-me/back/usrinfo/serializers.py changed, reloading.
2024-08-03 09:19:02,122: INFO: /Users/zmakhkha/Desktop/promote-me/back/usrinfo/serializers.py changed, reloading.
2024-08-03 09:19:11,188: INFO: /Users/zmakhkha/Desktop/promote-me/back/usrinfo/serializers.py changed, reloading.
2024-08-03 09:19:16,243: INFO: /Users/zmakhkha/Desktop/promote-me/back/usrinfo/serializers.py changed, reloading.
2024-08-03 09:19:21,847: INFO: /Users/zmakhkha/Desktop/promote-me/back/usrinfo/serializers.py changed, reloading.
2024-08-03 09:19:47,243: INFO: /Users/zmakhkha/Desktop/promote-me/back/usrinfo/serializers.py changed, reloading.
2024-08-03 09:19:55,895: INFO: /Users/zmakhkha/Desktop/promote-me/back/usrinfo/serializers.py changed, reloading.
2024-08-03 09:20:04,543: INFO: /Users/zmakhkha/Desktop/promote-me/back/usrinfo/serializers.py changed, reloading.
2024-08-03 09:20:10,134: INFO: /Users/zmakhkha/Desktop/promote-me/back/usrinfo/serializers.py changed, reloading.
2024-08-03 09:20:51,854: INFO: /Users/zmakhkha/Desktop/promote-me/back/usrinfo/serializers.py changed, reloading.
2024-08-03 09:20:57,460: INFO: /Users/zmakhkha/Desktop/promote-me/back/usrinfo/serializers.py changed, reloading.
2024-08-03 09:21:10,912: ERROR: Internal Server Error: /users/setting/
Traceback (most recent call last):
  File "/goinfre/zmakhkha/venv/lib/python3.9/site-packages/rest_framework/views.py", line 497, in dispatch
    self.initial(request, *args, **kwargs)
  File "/goinfre/zmakhkha/venv/lib/python3.9/site-packages/rest_framework/views.py", line 403, in initial
    self.format_kwarg = self.get_format_suffix(**kwargs)
  File "/goinfre/zmakhkha/venv/lib/python3.9/site-packages/rest_framework/views.py", line 253, in get_format_suffix
    if self.settings.FORMAT_SUFFIX_KWARG:
AttributeError: 'function' object has no attribute 'FORMAT_SUFFIX_KWARG'

During handling of the above exception, another exception occurred:

Traceback (most recent call last):
  File "/goinfre/zmakhkha/venv/lib/python3.9/site-packages/django/core/handlers/exception.py", line 55, in inner
    response = get_response(request)
  File "/goinfre/zmakhkha/venv/lib/python3.9/site-packages/django/core/handlers/base.py", line 197, in _get_response
    response = wrapped_callback(request, *callback_args, **callback_kwargs)
  File "/goinfre/zmakhkha/venv/lib/python3.9/site-packages/django/views/decorators/csrf.py", line 56, in wrapper_view
    return view_func(*args, **kwargs)
  File "/goinfre/zmakhkha/venv/lib/python3.9/site-packages/rest_framework/viewsets.py", line 124, in view
    return self.dispatch(request, *args, **kwargs)
  File "/goinfre/zmakhkha/venv/lib/python3.9/site-packages/rest_framework/views.py", line 509, in dispatch
    response = self.handle_exception(exc)
  File "/goinfre/zmakhkha/venv/lib/python3.9/site-packages/rest_framework/views.py", line 463, in handle_exception
    exception_handler = self.get_exception_handler()
  File "/goinfre/zmakhkha/venv/lib/python3.9/site-packages/rest_framework/views.py", line 298, in get_exception_handler
    return self.settings.EXCEPTION_HANDLER
AttributeError: 'function' object has no attribute 'EXCEPTION_HANDLER'
2024-08-03 09:22:15,347: INFO: /Users/zmakhkha/Desktop/promote-me/back/usrinfo/serializers.py changed, reloading.
2024-08-03 09:22:36,832: INFO: /Users/zmakhkha/Desktop/promote-me/back/usrinfo/serializers.py changed, reloading.
2024-08-03 09:23:10,813: ERROR: Internal Server Error: /users/setting/
Traceback (most recent call last):
  File "/goinfre/zmakhkha/venv/lib/python3.9/site-packages/rest_framework/views.py", line 497, in dispatch
    self.initial(request, *args, **kwargs)
  File "/goinfre/zmakhkha/venv/lib/python3.9/site-packages/rest_framework/views.py", line 403, in initial
    self.format_kwarg = self.get_format_suffix(**kwargs)
  File "/goinfre/zmakhkha/venv/lib/python3.9/site-packages/rest_framework/views.py", line 253, in get_format_suffix
    if self.settings.FORMAT_SUFFIX_KWARG:
AttributeError: 'function' object has no attribute 'FORMAT_SUFFIX_KWARG'

During handling of the above exception, another exception occurred:

Traceback (most recent call last):
  File "/goinfre/zmakhkha/venv/lib/python3.9/site-packages/django/core/handlers/exception.py", line 55, in inner
    response = get_response(request)
  File "/goinfre/zmakhkha/venv/lib/python3.9/site-packages/django/core/handlers/base.py", line 197, in _get_response
    response = wrapped_callback(request, *callback_args, **callback_kwargs)
  File "/goinfre/zmakhkha/venv/lib/python3.9/site-packages/django/views/decorators/csrf.py", line 56, in wrapper_view
    return view_func(*args, **kwargs)
  File "/goinfre/zmakhkha/venv/lib/python3.9/site-packages/rest_framework/viewsets.py", line 124, in view
    return self.dispatch(request, *args, **kwargs)
  File "/goinfre/zmakhkha/venv/lib/python3.9/site-packages/rest_framework/views.py", line 509, in dispatch
    response = self.handle_exception(exc)
  File "/goinfre/zmakhkha/venv/lib/python3.9/site-packages/rest_framework/views.py", line 463, in handle_exception
    exception_handler = self.get_exception_handler()
  File "/goinfre/zmakhkha/venv/lib/python3.9/site-packages/rest_framework/views.py", line 298, in get_exception_handler
    return self.settings.EXCEPTION_HANDLER
AttributeError: 'function' object has no attribute 'EXCEPTION_HANDLER'
2024-08-03 09:23:11,739: ERROR: Internal Server Error: /users/setting/
Traceback (most recent call last):
  File "/goinfre/zmakhkha/venv/lib/python3.9/site-packages/rest_framework/views.py", line 497, in dispatch
    self.initial(request, *args, **kwargs)
  File "/goinfre/zmakhkha/venv/lib/python3.9/site-packages/rest_framework/views.py", line 403, in initial
    self.format_kwarg = self.get_format_suffix(**kwargs)
  File "/goinfre/zmakhkha/venv/lib/python3.9/site-packages/rest_framework/views.py", line 253, in get_format_suffix
    if self.settings.FORMAT_SUFFIX_KWARG:
AttributeError: 'function' object has no attribute 'FORMAT_SUFFIX_KWARG'

During handling of the above exception, another exception occurred:

Traceback (most recent call last):
  File "/goinfre/zmakhkha/venv/lib/python3.9/site-packages/django/core/handlers/exception.py", line 55, in inner
    response = get_response(request)
  File "/goinfre/zmakhkha/venv/lib/python3.9/site-packages/django/core/handlers/base.py", line 197, in _get_response
    response = wrapped_callback(request, *callback_args, **callback_kwargs)
  File "/goinfre/zmakhkha/venv/lib/python3.9/site-packages/django/views/decorators/csrf.py", line 56, in wrapper_view
    return view_func(*args, **kwargs)
  File "/goinfre/zmakhkha/venv/lib/python3.9/site-packages/rest_framework/viewsets.py", line 124, in view
    return self.dispatch(request, *args, **kwargs)
  File "/goinfre/zmakhkha/venv/lib/python3.9/site-packages/rest_framework/views.py", line 509, in dispatch
    response = self.handle_exception(exc)
  File "/goinfre/zmakhkha/venv/lib/python3.9/site-packages/rest_framework/views.py", line 463, in handle_exception
    exception_handler = self.get_exception_handler()
  File "/goinfre/zmakhkha/venv/lib/python3.9/site-packages/rest_framework/views.py", line 298, in get_exception_handler
    return self.settings.EXCEPTION_HANDLER
AttributeError: 'function' object has no attribute 'EXCEPTION_HANDLER'
2024-08-03 09:23:12,298: ERROR: Internal Server Error: /users/setting/
Traceback (most recent call last):
  File "/goinfre/zmakhkha/venv/lib/python3.9/site-packages/rest_framework/views.py", line 497, in dispatch
    self.initial(request, *args, **kwargs)
  File "/goinfre/zmakhkha/venv/lib/python3.9/site-packages/rest_framework/views.py", line 403, in initial
    self.format_kwarg = self.get_format_suffix(**kwargs)
  File "/goinfre/zmakhkha/venv/lib/python3.9/site-packages/rest_framework/views.py", line 253, in get_format_suffix
    if self.settings.FORMAT_SUFFIX_KWARG:
AttributeError: 'function' object has no attribute 'FORMAT_SUFFIX_KWARG'

During handling of the above exception, another exception occurred:

Traceback (most recent call last):
  File "/goinfre/zmakhkha/venv/lib/python3.9/site-packages/django/core/handlers/exception.py", line 55, in inner
    response = get_response(request)
  File "/goinfre/zmakhkha/venv/lib/python3.9/site-packages/django/core/handlers/base.py", line 197, in _get_response
    response = wrapped_callback(request, *callback_args, **callback_kwargs)
  File "/goinfre/zmakhkha/venv/lib/python3.9/site-packages/django/views/decorators/csrf.py", line 56, in wrapper_view
    return view_func(*args, **kwargs)
  File "/goinfre/zmakhkha/venv/lib/python3.9/site-packages/rest_framework/viewsets.py", line 124, in view
    return self.dispatch(request, *args, **kwargs)
  File "/goinfre/zmakhkha/venv/lib/python3.9/site-packages/rest_framework/views.py", line 509, in dispatch
    response = self.handle_exception(exc)
  File "/goinfre/zmakhkha/venv/lib/python3.9/site-packages/rest_framework/views.py", line 463, in handle_exception
    exception_handler = self.get_exception_handler()
  File "/goinfre/zmakhkha/venv/lib/python3.9/site-packages/rest_framework/views.py", line 298, in get_exception_handler
    return self.settings.EXCEPTION_HANDLER
AttributeError: 'function' object has no attribute 'EXCEPTION_HANDLER'
2024-08-03 09:23:23,617: INFO: /Users/zmakhkha/Desktop/promote-me/back/usrinfo/views.py changed, reloading.
2024-08-03 09:23:26,076: ERROR: Internal Server Error: /users/setting/
Traceback (most recent call last):
  File "/goinfre/zmakhkha/venv/lib/python3.9/site-packages/rest_framework/views.py", line 497, in dispatch
    self.initial(request, *args, **kwargs)
  File "/goinfre/zmakhkha/venv/lib/python3.9/site-packages/rest_framework/views.py", line 403, in initial
    self.format_kwarg = self.get_format_suffix(**kwargs)
  File "/goinfre/zmakhkha/venv/lib/python3.9/site-packages/rest_framework/views.py", line 253, in get_format_suffix
    if self.settings.FORMAT_SUFFIX_KWARG:
AttributeError: 'function' object has no attribute 'FORMAT_SUFFIX_KWARG'

During handling of the above exception, another exception occurred:

Traceback (most recent call last):
  File "/goinfre/zmakhkha/venv/lib/python3.9/site-packages/django/core/handlers/exception.py", line 55, in inner
    response = get_response(request)
  File "/goinfre/zmakhkha/venv/lib/python3.9/site-packages/django/core/handlers/base.py", line 197, in _get_response
    response = wrapped_callback(request, *callback_args, **callback_kwargs)
  File "/goinfre/zmakhkha/venv/lib/python3.9/site-packages/django/views/decorators/csrf.py", line 56, in wrapper_view
    return view_func(*args, **kwargs)
  File "/goinfre/zmakhkha/venv/lib/python3.9/site-packages/rest_framework/viewsets.py", line 124, in view
    return self.dispatch(request, *args, **kwargs)
  File "/goinfre/zmakhkha/venv/lib/python3.9/site-packages/rest_framework/views.py", line 509, in dispatch
    response = self.handle_exception(exc)
  File "/goinfre/zmakhkha/venv/lib/python3.9/site-packages/rest_framework/views.py", line 463, in handle_exception
    exception_handler = self.get_exception_handler()
  File "/goinfre/zmakhkha/venv/lib/python3.9/site-packages/rest_framework/views.py", line 298, in get_exception_handler
    return self.settings.EXCEPTION_HANDLER
AttributeError: 'function' object has no attribute 'EXCEPTION_HANDLER'
2024-08-03 09:23:32,658: ERROR: Internal Server Error: /users/settings/
Traceback (most recent call last):
  File "/goinfre/zmakhkha/venv/lib/python3.9/site-packages/rest_framework/views.py", line 497, in dispatch
    self.initial(request, *args, **kwargs)
  File "/goinfre/zmakhkha/venv/lib/python3.9/site-packages/rest_framework/views.py", line 403, in initial
    self.format_kwarg = self.get_format_suffix(**kwargs)
  File "/goinfre/zmakhkha/venv/lib/python3.9/site-packages/rest_framework/views.py", line 253, in get_format_suffix
    if self.settings.FORMAT_SUFFIX_KWARG:
AttributeError: 'function' object has no attribute 'FORMAT_SUFFIX_KWARG'

During handling of the above exception, another exception occurred:

Traceback (most recent call last):
  File "/goinfre/zmakhkha/venv/lib/python3.9/site-packages/django/core/handlers/exception.py", line 55, in inner
    response = get_response(request)
  File "/goinfre/zmakhkha/venv/lib/python3.9/site-packages/django/core/handlers/base.py", line 197, in _get_response
    response = wrapped_callback(request, *callback_args, **callback_kwargs)
  File "/goinfre/zmakhkha/venv/lib/python3.9/site-packages/django/views/decorators/csrf.py", line 56, in wrapper_view
    return view_func(*args, **kwargs)
  File "/goinfre/zmakhkha/venv/lib/python3.9/site-packages/rest_framework/viewsets.py", line 124, in view
    return self.dispatch(request, *args, **kwargs)
  File "/goinfre/zmakhkha/venv/lib/python3.9/site-packages/rest_framework/views.py", line 509, in dispatch
    response = self.handle_exception(exc)
  File "/goinfre/zmakhkha/venv/lib/python3.9/site-packages/rest_framework/views.py", line 463, in handle_exception
    exception_handler = self.get_exception_handler()
  File "/goinfre/zmakhkha/venv/lib/python3.9/site-packages/rest_framework/views.py", line 298, in get_exception_handler
    return self.settings.EXCEPTION_HANDLER
AttributeError: 'function' object has no attribute 'EXCEPTION_HANDLER'
2024-08-03 09:23:52,296: ERROR: Internal Server Error: /users/settings/
Traceback (most recent call last):
  File "/goinfre/zmakhkha/venv/lib/python3.9/site-packages/rest_framework/views.py", line 497, in dispatch
    self.initial(request, *args, **kwargs)
  File "/goinfre/zmakhkha/venv/lib/python3.9/site-packages/rest_framework/views.py", line 403, in initial
    self.format_kwarg = self.get_format_suffix(**kwargs)
  File "/goinfre/zmakhkha/venv/lib/python3.9/site-packages/rest_framework/views.py", line 253, in get_format_suffix
    if self.settings.FORMAT_SUFFIX_KWARG:
AttributeError: 'function' object has no attribute 'FORMAT_SUFFIX_KWARG'

During handling of the above exception, another exception occurred:

Traceback (most recent call last):
  File "/goinfre/zmakhkha/venv/lib/python3.9/site-packages/django/core/handlers/exception.py", line 55, in inner
    response = get_response(request)
  File "/goinfre/zmakhkha/venv/lib/python3.9/site-packages/django/core/handlers/base.py", line 197, in _get_response
    response = wrapped_callback(request, *callback_args, **callback_kwargs)
  File "/goinfre/zmakhkha/venv/lib/python3.9/site-packages/django/views/decorators/csrf.py", line 56, in wrapper_view
    return view_func(*args, **kwargs)
  File "/goinfre/zmakhkha/venv/lib/python3.9/site-packages/rest_framework/viewsets.py", line 124, in view
    return self.dispatch(request, *args, **kwargs)
  File "/goinfre/zmakhkha/venv/lib/python3.9/site-packages/rest_framework/views.py", line 509, in dispatch
    response = self.handle_exception(exc)
  File "/goinfre/zmakhkha/venv/lib/python3.9/site-packages/rest_framework/views.py", line 463, in handle_exception
    exception_handler = self.get_exception_handler()
  File "/goinfre/zmakhkha/venv/lib/python3.9/site-packages/rest_framework/views.py", line 298, in get_exception_handler
    return self.settings.EXCEPTION_HANDLER
AttributeError: 'function' object has no attribute 'EXCEPTION_HANDLER'
2024-08-03 09:23:52,855: ERROR: Internal Server Error: /users/settings/
Traceback (most recent call last):
  File "/goinfre/zmakhkha/venv/lib/python3.9/site-packages/rest_framework/views.py", line 497, in dispatch
    self.initial(request, *args, **kwargs)
  File "/goinfre/zmakhkha/venv/lib/python3.9/site-packages/rest_framework/views.py", line 403, in initial
    self.format_kwarg = self.get_format_suffix(**kwargs)
  File "/goinfre/zmakhkha/venv/lib/python3.9/site-packages/rest_framework/views.py", line 253, in get_format_suffix
    if self.settings.FORMAT_SUFFIX_KWARG:
AttributeError: 'function' object has no attribute 'FORMAT_SUFFIX_KWARG'

During handling of the above exception, another exception occurred:

Traceback (most recent call last):
  File "/goinfre/zmakhkha/venv/lib/python3.9/site-packages/django/core/handlers/exception.py", line 55, in inner
    response = get_response(request)
  File "/goinfre/zmakhkha/venv/lib/python3.9/site-packages/django/core/handlers/base.py", line 197, in _get_response
    response = wrapped_callback(request, *callback_args, **callback_kwargs)
  File "/goinfre/zmakhkha/venv/lib/python3.9/site-packages/django/views/decorators/csrf.py", line 56, in wrapper_view
    return view_func(*args, **kwargs)
  File "/goinfre/zmakhkha/venv/lib/python3.9/site-packages/rest_framework/viewsets.py", line 124, in view
    return self.dispatch(request, *args, **kwargs)
  File "/goinfre/zmakhkha/venv/lib/python3.9/site-packages/rest_framework/views.py", line 509, in dispatch
    response = self.handle_exception(exc)
  File "/goinfre/zmakhkha/venv/lib/python3.9/site-packages/rest_framework/views.py", line 463, in handle_exception
    exception_handler = self.get_exception_handler()
  File "/goinfre/zmakhkha/venv/lib/python3.9/site-packages/rest_framework/views.py", line 298, in get_exception_handler
    return self.settings.EXCEPTION_HANDLER
AttributeError: 'function' object has no attribute 'EXCEPTION_HANDLER'
2024-08-03 09:23:52,856: INFO: /Users/zmakhkha/Desktop/promote-me/back/usrinfo/serializers.py changed, reloading.
2024-08-03 09:23:54,058: ERROR: Internal Server Error: /users/settings/
Traceback (most recent call last):
  File "/goinfre/zmakhkha/venv/lib/python3.9/site-packages/rest_framework/views.py", line 497, in dispatch
    self.initial(request, *args, **kwargs)
  File "/goinfre/zmakhkha/venv/lib/python3.9/site-packages/rest_framework/views.py", line 403, in initial
    self.format_kwarg = self.get_format_suffix(**kwargs)
  File "/goinfre/zmakhkha/venv/lib/python3.9/site-packages/rest_framework/views.py", line 253, in get_format_suffix
    if self.settings.FORMAT_SUFFIX_KWARG:
AttributeError: 'function' object has no attribute 'FORMAT_SUFFIX_KWARG'

During handling of the above exception, another exception occurred:

Traceback (most recent call last):
  File "/goinfre/zmakhkha/venv/lib/python3.9/site-packages/django/core/handlers/exception.py", line 55, in inner
    response = get_response(request)
  File "/goinfre/zmakhkha/venv/lib/python3.9/site-packages/django/core/handlers/base.py", line 197, in _get_response
    response = wrapped_callback(request, *callback_args, **callback_kwargs)
  File "/goinfre/zmakhkha/venv/lib/python3.9/site-packages/django/views/decorators/csrf.py", line 56, in wrapper_view
    return view_func(*args, **kwargs)
  File "/goinfre/zmakhkha/venv/lib/python3.9/site-packages/rest_framework/viewsets.py", line 124, in view
    return self.dispatch(request, *args, **kwargs)
  File "/goinfre/zmakhkha/venv/lib/python3.9/site-packages/rest_framework/views.py", line 509, in dispatch
    response = self.handle_exception(exc)
  File "/goinfre/zmakhkha/venv/lib/python3.9/site-packages/rest_framework/views.py", line 463, in handle_exception
    exception_handler = self.get_exception_handler()
  File "/goinfre/zmakhkha/venv/lib/python3.9/site-packages/rest_framework/views.py", line 298, in get_exception_handler
    return self.settings.EXCEPTION_HANDLER
AttributeError: 'function' object has no attribute 'EXCEPTION_HANDLER'
2024-08-03 09:23:54,952: ERROR: Internal Server Error: /users/settings/
Traceback (most recent call last):
  File "/goinfre/zmakhkha/venv/lib/python3.9/site-packages/rest_framework/views.py", line 497, in dispatch
    self.initial(request, *args, **kwargs)
  File "/goinfre/zmakhkha/venv/lib/python3.9/site-packages/rest_framework/views.py", line 403, in initial
    self.format_kwarg = self.get_format_suffix(**kwargs)
  File "/goinfre/zmakhkha/venv/lib/python3.9/site-packages/rest_framework/views.py", line 253, in get_format_suffix
    if self.settings.FORMAT_SUFFIX_KWARG:
AttributeError: 'function' object has no attribute 'FORMAT_SUFFIX_KWARG'

During handling of the above exception, another exception occurred:

Traceback (most recent call last):
  File "/goinfre/zmakhkha/venv/lib/python3.9/site-packages/django/core/handlers/exception.py", line 55, in inner
    response = get_response(request)
  File "/goinfre/zmakhkha/venv/lib/python3.9/site-packages/django/core/handlers/base.py", line 197, in _get_response
    response = wrapped_callback(request, *callback_args, **callback_kwargs)
  File "/goinfre/zmakhkha/venv/lib/python3.9/site-packages/django/views/decorators/csrf.py", line 56, in wrapper_view
    return view_func(*args, **kwargs)
  File "/goinfre/zmakhkha/venv/lib/python3.9/site-packages/rest_framework/viewsets.py", line 124, in view
    return self.dispatch(request, *args, **kwargs)
  File "/goinfre/zmakhkha/venv/lib/python3.9/site-packages/rest_framework/views.py", line 509, in dispatch
    response = self.handle_exception(exc)
  File "/goinfre/zmakhkha/venv/lib/python3.9/site-packages/rest_framework/views.py", line 463, in handle_exception
    exception_handler = self.get_exception_handler()
  File "/goinfre/zmakhkha/venv/lib/python3.9/site-packages/rest_framework/views.py", line 298, in get_exception_handler
    return self.settings.EXCEPTION_HANDLER
AttributeError: 'function' object has no attribute 'EXCEPTION_HANDLER'
2024-08-03 09:24:09,897: INFO: /Users/zmakhkha/Desktop/promote-me/back/usrinfo/serializers.py changed, reloading.
2024-08-03 09:24:31,988: INFO: /Users/zmakhkha/Desktop/promote-me/back/usrinfo/serializers.py changed, reloading.
2024-08-03 09:24:45,934: ERROR: Internal Server Error: /users/settings/
Traceback (most recent call last):
  File "/goinfre/zmakhkha/venv/lib/python3.9/site-packages/rest_framework/views.py", line 497, in dispatch
    self.initial(request, *args, **kwargs)
  File "/goinfre/zmakhkha/venv/lib/python3.9/site-packages/rest_framework/views.py", line 403, in initial
    self.format_kwarg = self.get_format_suffix(**kwargs)
  File "/goinfre/zmakhkha/venv/lib/python3.9/site-packages/rest_framework/views.py", line 253, in get_format_suffix
    if self.settings.FORMAT_SUFFIX_KWARG:
AttributeError: 'function' object has no attribute 'FORMAT_SUFFIX_KWARG'

During handling of the above exception, another exception occurred:

Traceback (most recent call last):
  File "/goinfre/zmakhkha/venv/lib/python3.9/site-packages/django/core/handlers/exception.py", line 55, in inner
    response = get_response(request)
  File "/goinfre/zmakhkha/venv/lib/python3.9/site-packages/django/core/handlers/base.py", line 197, in _get_response
    response = wrapped_callback(request, *callback_args, **callback_kwargs)
  File "/goinfre/zmakhkha/venv/lib/python3.9/site-packages/django/views/decorators/csrf.py", line 56, in wrapper_view
    return view_func(*args, **kwargs)
  File "/goinfre/zmakhkha/venv/lib/python3.9/site-packages/rest_framework/viewsets.py", line 124, in view
    return self.dispatch(request, *args, **kwargs)
  File "/goinfre/zmakhkha/venv/lib/python3.9/site-packages/rest_framework/views.py", line 509, in dispatch
    response = self.handle_exception(exc)
  File "/goinfre/zmakhkha/venv/lib/python3.9/site-packages/rest_framework/views.py", line 463, in handle_exception
    exception_handler = self.get_exception_handler()
  File "/goinfre/zmakhkha/venv/lib/python3.9/site-packages/rest_framework/views.py", line 298, in get_exception_handler
    return self.settings.EXCEPTION_HANDLER
AttributeError: 'function' object has no attribute 'EXCEPTION_HANDLER'
2024-08-03 09:24:46,599: ERROR: Internal Server Error: /users/settings/
Traceback (most recent call last):
  File "/goinfre/zmakhkha/venv/lib/python3.9/site-packages/rest_framework/views.py", line 497, in dispatch
    self.initial(request, *args, **kwargs)
  File "/goinfre/zmakhkha/venv/lib/python3.9/site-packages/rest_framework/views.py", line 403, in initial
    self.format_kwarg = self.get_format_suffix(**kwargs)
  File "/goinfre/zmakhkha/venv/lib/python3.9/site-packages/rest_framework/views.py", line 253, in get_format_suffix
    if self.settings.FORMAT_SUFFIX_KWARG:
AttributeError: 'function' object has no attribute 'FORMAT_SUFFIX_KWARG'

During handling of the above exception, another exception occurred:

Traceback (most recent call last):
  File "/goinfre/zmakhkha/venv/lib/python3.9/site-packages/django/core/handlers/exception.py", line 55, in inner
    response = get_response(request)
  File "/goinfre/zmakhkha/venv/lib/python3.9/site-packages/django/core/handlers/base.py", line 197, in _get_response
    response = wrapped_callback(request, *callback_args, **callback_kwargs)
  File "/goinfre/zmakhkha/venv/lib/python3.9/site-packages/django/views/decorators/csrf.py", line 56, in wrapper_view
    return view_func(*args, **kwargs)
  File "/goinfre/zmakhkha/venv/lib/python3.9/site-packages/rest_framework/viewsets.py", line 124, in view
    return self.dispatch(request, *args, **kwargs)
  File "/goinfre/zmakhkha/venv/lib/python3.9/site-packages/rest_framework/views.py", line 509, in dispatch
    response = self.handle_exception(exc)
  File "/goinfre/zmakhkha/venv/lib/python3.9/site-packages/rest_framework/views.py", line 463, in handle_exception
    exception_handler = self.get_exception_handler()
  File "/goinfre/zmakhkha/venv/lib/python3.9/site-packages/rest_framework/views.py", line 298, in get_exception_handler
    return self.settings.EXCEPTION_HANDLER
AttributeError: 'function' object has no attribute 'EXCEPTION_HANDLER'
2024-08-03 09:24:47,044: ERROR: Internal Server Error: /users/settings/
Traceback (most recent call last):
  File "/goinfre/zmakhkha/venv/lib/python3.9/site-packages/rest_framework/views.py", line 497, in dispatch
    self.initial(request, *args, **kwargs)
  File "/goinfre/zmakhkha/venv/lib/python3.9/site-packages/rest_framework/views.py", line 403, in initial
    self.format_kwarg = self.get_format_suffix(**kwargs)
  File "/goinfre/zmakhkha/venv/lib/python3.9/site-packages/rest_framework/views.py", line 253, in get_format_suffix
    if self.settings.FORMAT_SUFFIX_KWARG:
AttributeError: 'function' object has no attribute 'FORMAT_SUFFIX_KWARG'

During handling of the above exception, another exception occurred:

Traceback (most recent call last):
  File "/goinfre/zmakhkha/venv/lib/python3.9/site-packages/django/core/handlers/exception.py", line 55, in inner
    response = get_response(request)
  File "/goinfre/zmakhkha/venv/lib/python3.9/site-packages/django/core/handlers/base.py", line 197, in _get_response
    response = wrapped_callback(request, *callback_args, **callback_kwargs)
  File "/goinfre/zmakhkha/venv/lib/python3.9/site-packages/django/views/decorators/csrf.py", line 56, in wrapper_view
    return view_func(*args, **kwargs)
  File "/goinfre/zmakhkha/venv/lib/python3.9/site-packages/rest_framework/viewsets.py", line 124, in view
    return self.dispatch(request, *args, **kwargs)
  File "/goinfre/zmakhkha/venv/lib/python3.9/site-packages/rest_framework/views.py", line 509, in dispatch
    response = self.handle_exception(exc)
  File "/goinfre/zmakhkha/venv/lib/python3.9/site-packages/rest_framework/views.py", line 463, in handle_exception
    exception_handler = self.get_exception_handler()
  File "/goinfre/zmakhkha/venv/lib/python3.9/site-packages/rest_framework/views.py", line 298, in get_exception_handler
    return self.settings.EXCEPTION_HANDLER
AttributeError: 'function' object has no attribute 'EXCEPTION_HANDLER'
2024-08-03 09:24:51,163: INFO: /Users/zmakhkha/Desktop/promote-me/back/usrinfo/views.py changed, reloading.
2024-08-03 09:25:13,479: ERROR: Internal Server Error: /users/settings/
Traceback (most recent call last):
  File "/goinfre/zmakhkha/venv/lib/python3.9/site-packages/rest_framework/views.py", line 497, in dispatch
    self.initial(request, *args, **kwargs)
  File "/goinfre/zmakhkha/venv/lib/python3.9/site-packages/rest_framework/views.py", line 403, in initial
    self.format_kwarg = self.get_format_suffix(**kwargs)
  File "/goinfre/zmakhkha/venv/lib/python3.9/site-packages/rest_framework/views.py", line 253, in get_format_suffix
    if self.settings.FORMAT_SUFFIX_KWARG:
AttributeError: 'function' object has no attribute 'FORMAT_SUFFIX_KWARG'

During handling of the above exception, another exception occurred:

Traceback (most recent call last):
  File "/goinfre/zmakhkha/venv/lib/python3.9/site-packages/django/core/handlers/exception.py", line 55, in inner
    response = get_response(request)
  File "/goinfre/zmakhkha/venv/lib/python3.9/site-packages/django/core/handlers/base.py", line 197, in _get_response
    response = wrapped_callback(request, *callback_args, **callback_kwargs)
  File "/goinfre/zmakhkha/venv/lib/python3.9/site-packages/django/views/decorators/csrf.py", line 56, in wrapper_view
    return view_func(*args, **kwargs)
  File "/goinfre/zmakhkha/venv/lib/python3.9/site-packages/rest_framework/viewsets.py", line 124, in view
    return self.dispatch(request, *args, **kwargs)
  File "/goinfre/zmakhkha/venv/lib/python3.9/site-packages/rest_framework/views.py", line 509, in dispatch
    response = self.handle_exception(exc)
  File "/goinfre/zmakhkha/venv/lib/python3.9/site-packages/rest_framework/views.py", line 463, in handle_exception
    exception_handler = self.get_exception_handler()
  File "/goinfre/zmakhkha/venv/lib/python3.9/site-packages/rest_framework/views.py", line 298, in get_exception_handler
    return self.settings.EXCEPTION_HANDLER
AttributeError: 'function' object has no attribute 'EXCEPTION_HANDLER'
2024-08-03 09:25:14,087: ERROR: Internal Server Error: /users/settings/
Traceback (most recent call last):
  File "/goinfre/zmakhkha/venv/lib/python3.9/site-packages/rest_framework/views.py", line 497, in dispatch
    self.initial(request, *args, **kwargs)
  File "/goinfre/zmakhkha/venv/lib/python3.9/site-packages/rest_framework/views.py", line 403, in initial
    self.format_kwarg = self.get_format_suffix(**kwargs)
  File "/goinfre/zmakhkha/venv/lib/python3.9/site-packages/rest_framework/views.py", line 253, in get_format_suffix
    if self.settings.FORMAT_SUFFIX_KWARG:
AttributeError: 'function' object has no attribute 'FORMAT_SUFFIX_KWARG'

During handling of the above exception, another exception occurred:

Traceback (most recent call last):
  File "/goinfre/zmakhkha/venv/lib/python3.9/site-packages/django/core/handlers/exception.py", line 55, in inner
    response = get_response(request)
  File "/goinfre/zmakhkha/venv/lib/python3.9/site-packages/django/core/handlers/base.py", line 197, in _get_response
    response = wrapped_callback(request, *callback_args, **callback_kwargs)
  File "/goinfre/zmakhkha/venv/lib/python3.9/site-packages/django/views/decorators/csrf.py", line 56, in wrapper_view
    return view_func(*args, **kwargs)
  File "/goinfre/zmakhkha/venv/lib/python3.9/site-packages/rest_framework/viewsets.py", line 124, in view
    return self.dispatch(request, *args, **kwargs)
  File "/goinfre/zmakhkha/venv/lib/python3.9/site-packages/rest_framework/views.py", line 509, in dispatch
    response = self.handle_exception(exc)
  File "/goinfre/zmakhkha/venv/lib/python3.9/site-packages/rest_framework/views.py", line 463, in handle_exception
    exception_handler = self.get_exception_handler()
  File "/goinfre/zmakhkha/venv/lib/python3.9/site-packages/rest_framework/views.py", line 298, in get_exception_handler
    return self.settings.EXCEPTION_HANDLER
AttributeError: 'function' object has no attribute 'EXCEPTION_HANDLER'
2024-08-03 09:25:20,932: INFO: /Users/zmakhkha/Desktop/promote-me/back/usrinfo/serializers.py changed, reloading.
2024-08-03 09:25:22,452: INFO: /Users/zmakhkha/Desktop/promote-me/back/usrinfo/serializers.py changed, reloading.
2024-08-03 09:25:30,151: ERROR: Internal Server Error: /users/settings/
Traceback (most recent call last):
  File "/goinfre/zmakhkha/venv/lib/python3.9/site-packages/rest_framework/views.py", line 497, in dispatch
    self.initial(request, *args, **kwargs)
  File "/goinfre/zmakhkha/venv/lib/python3.9/site-packages/rest_framework/views.py", line 403, in initial
    self.format_kwarg = self.get_format_suffix(**kwargs)
  File "/goinfre/zmakhkha/venv/lib/python3.9/site-packages/rest_framework/views.py", line 253, in get_format_suffix
    if self.settings.FORMAT_SUFFIX_KWARG:
AttributeError: 'function' object has no attribute 'FORMAT_SUFFIX_KWARG'

During handling of the above exception, another exception occurred:

Traceback (most recent call last):
  File "/goinfre/zmakhkha/venv/lib/python3.9/site-packages/django/core/handlers/exception.py", line 55, in inner
    response = get_response(request)
  File "/goinfre/zmakhkha/venv/lib/python3.9/site-packages/django/core/handlers/base.py", line 197, in _get_response
    response = wrapped_callback(request, *callback_args, **callback_kwargs)
  File "/goinfre/zmakhkha/venv/lib/python3.9/site-packages/django/views/decorators/csrf.py", line 56, in wrapper_view
    return view_func(*args, **kwargs)
  File "/goinfre/zmakhkha/venv/lib/python3.9/site-packages/rest_framework/viewsets.py", line 124, in view
    return self.dispatch(request, *args, **kwargs)
  File "/goinfre/zmakhkha/venv/lib/python3.9/site-packages/rest_framework/views.py", line 509, in dispatch
    response = self.handle_exception(exc)
  File "/goinfre/zmakhkha/venv/lib/python3.9/site-packages/rest_framework/views.py", line 463, in handle_exception
    exception_handler = self.get_exception_handler()
  File "/goinfre/zmakhkha/venv/lib/python3.9/site-packages/rest_framework/views.py", line 298, in get_exception_handler
    return self.settings.EXCEPTION_HANDLER
AttributeError: 'function' object has no attribute 'EXCEPTION_HANDLER'
2024-08-03 09:25:30,774: ERROR: Internal Server Error: /users/settings/
Traceback (most recent call last):
  File "/goinfre/zmakhkha/venv/lib/python3.9/site-packages/rest_framework/views.py", line 497, in dispatch
    self.initial(request, *args, **kwargs)
  File "/goinfre/zmakhkha/venv/lib/python3.9/site-packages/rest_framework/views.py", line 403, in initial
    self.format_kwarg = self.get_format_suffix(**kwargs)
  File "/goinfre/zmakhkha/venv/lib/python3.9/site-packages/rest_framework/views.py", line 253, in get_format_suffix
    if self.settings.FORMAT_SUFFIX_KWARG:
AttributeError: 'function' object has no attribute 'FORMAT_SUFFIX_KWARG'

During handling of the above exception, another exception occurred:

Traceback (most recent call last):
  File "/goinfre/zmakhkha/venv/lib/python3.9/site-packages/django/core/handlers/exception.py", line 55, in inner
    response = get_response(request)
  File "/goinfre/zmakhkha/venv/lib/python3.9/site-packages/django/core/handlers/base.py", line 197, in _get_response
    response = wrapped_callback(request, *callback_args, **callback_kwargs)
  File "/goinfre/zmakhkha/venv/lib/python3.9/site-packages/django/views/decorators/csrf.py", line 56, in wrapper_view
    return view_func(*args, **kwargs)
  File "/goinfre/zmakhkha/venv/lib/python3.9/site-packages/rest_framework/viewsets.py", line 124, in view
    return self.dispatch(request, *args, **kwargs)
  File "/goinfre/zmakhkha/venv/lib/python3.9/site-packages/rest_framework/views.py", line 509, in dispatch
    response = self.handle_exception(exc)
  File "/goinfre/zmakhkha/venv/lib/python3.9/site-packages/rest_framework/views.py", line 463, in handle_exception
    exception_handler = self.get_exception_handler()
  File "/goinfre/zmakhkha/venv/lib/python3.9/site-packages/rest_framework/views.py", line 298, in get_exception_handler
    return self.settings.EXCEPTION_HANDLER
AttributeError: 'function' object has no attribute 'EXCEPTION_HANDLER'
2024-08-03 09:25:37,731: INFO: /Users/zmakhkha/Desktop/promote-me/back/usrinfo/serializers.py changed, reloading.
2024-08-03 09:25:40,276: INFO: /Users/zmakhkha/Desktop/promote-me/back/usrinfo/serializers.py changed, reloading.
2024-08-03 09:25:41,834: ERROR: Internal Server Error: /users/settings/
Traceback (most recent call last):
  File "/goinfre/zmakhkha/venv/lib/python3.9/site-packages/rest_framework/views.py", line 497, in dispatch
    self.initial(request, *args, **kwargs)
  File "/goinfre/zmakhkha/venv/lib/python3.9/site-packages/rest_framework/views.py", line 403, in initial
    self.format_kwarg = self.get_format_suffix(**kwargs)
  File "/goinfre/zmakhkha/venv/lib/python3.9/site-packages/rest_framework/views.py", line 253, in get_format_suffix
    if self.settings.FORMAT_SUFFIX_KWARG:
AttributeError: 'function' object has no attribute 'FORMAT_SUFFIX_KWARG'

During handling of the above exception, another exception occurred:

Traceback (most recent call last):
  File "/goinfre/zmakhkha/venv/lib/python3.9/site-packages/django/core/handlers/exception.py", line 55, in inner
    response = get_response(request)
  File "/goinfre/zmakhkha/venv/lib/python3.9/site-packages/django/core/handlers/base.py", line 197, in _get_response
    response = wrapped_callback(request, *callback_args, **callback_kwargs)
  File "/goinfre/zmakhkha/venv/lib/python3.9/site-packages/django/views/decorators/csrf.py", line 56, in wrapper_view
    return view_func(*args, **kwargs)
  File "/goinfre/zmakhkha/venv/lib/python3.9/site-packages/rest_framework/viewsets.py", line 124, in view
    return self.dispatch(request, *args, **kwargs)
  File "/goinfre/zmakhkha/venv/lib/python3.9/site-packages/rest_framework/views.py", line 509, in dispatch
    response = self.handle_exception(exc)
  File "/goinfre/zmakhkha/venv/lib/python3.9/site-packages/rest_framework/views.py", line 463, in handle_exception
    exception_handler = self.get_exception_handler()
  File "/goinfre/zmakhkha/venv/lib/python3.9/site-packages/rest_framework/views.py", line 298, in get_exception_handler
    return self.settings.EXCEPTION_HANDLER
AttributeError: 'function' object has no attribute 'EXCEPTION_HANDLER'
2024-08-03 09:25:45,961: INFO: /Users/zmakhkha/Desktop/promote-me/back/usrinfo/serializers.py changed, reloading.
2024-08-03 09:26:21,968: INFO: /Users/zmakhkha/Desktop/promote-me/back/usrinfo/serializers.py changed, reloading.
2024-08-03 09:26:25,546: INFO: /Users/zmakhkha/Desktop/promote-me/back/usrinfo/serializers.py changed, reloading.
2024-08-03 09:27:09,007: INFO: /Users/zmakhkha/Desktop/promote-me/back/usrinfo/serializers.py changed, reloading.
2024-08-03 09:27:13,574: ERROR: Internal Server Error: /users/settings/
Traceback (most recent call last):
  File "/goinfre/zmakhkha/venv/lib/python3.9/site-packages/rest_framework/views.py", line 497, in dispatch
    self.initial(request, *args, **kwargs)
  File "/goinfre/zmakhkha/venv/lib/python3.9/site-packages/rest_framework/views.py", line 403, in initial
    self.format_kwarg = self.get_format_suffix(**kwargs)
  File "/goinfre/zmakhkha/venv/lib/python3.9/site-packages/rest_framework/views.py", line 253, in get_format_suffix
    if self.settings.FORMAT_SUFFIX_KWARG:
AttributeError: 'function' object has no attribute 'FORMAT_SUFFIX_KWARG'

During handling of the above exception, another exception occurred:

Traceback (most recent call last):
  File "/goinfre/zmakhkha/venv/lib/python3.9/site-packages/django/core/handlers/exception.py", line 55, in inner
    response = get_response(request)
  File "/goinfre/zmakhkha/venv/lib/python3.9/site-packages/django/core/handlers/base.py", line 197, in _get_response
    response = wrapped_callback(request, *callback_args, **callback_kwargs)
  File "/goinfre/zmakhkha/venv/lib/python3.9/site-packages/django/views/decorators/csrf.py", line 56, in wrapper_view
    return view_func(*args, **kwargs)
  File "/goinfre/zmakhkha/venv/lib/python3.9/site-packages/rest_framework/viewsets.py", line 124, in view
    return self.dispatch(request, *args, **kwargs)
  File "/goinfre/zmakhkha/venv/lib/python3.9/site-packages/rest_framework/views.py", line 509, in dispatch
    response = self.handle_exception(exc)
  File "/goinfre/zmakhkha/venv/lib/python3.9/site-packages/rest_framework/views.py", line 463, in handle_exception
    exception_handler = self.get_exception_handler()
  File "/goinfre/zmakhkha/venv/lib/python3.9/site-packages/rest_framework/views.py", line 298, in get_exception_handler
    return self.settings.EXCEPTION_HANDLER
AttributeError: 'function' object has no attribute 'EXCEPTION_HANDLER'
2024-08-03 09:27:22,818: WARNING: Not Found: /udasasdads
2024-08-03 09:27:27,227: ERROR: Internal Server Error: /users/setting/
Traceback (most recent call last):
  File "/goinfre/zmakhkha/venv/lib/python3.9/site-packages/rest_framework/views.py", line 497, in dispatch
    self.initial(request, *args, **kwargs)
  File "/goinfre/zmakhkha/venv/lib/python3.9/site-packages/rest_framework/views.py", line 403, in initial
    self.format_kwarg = self.get_format_suffix(**kwargs)
  File "/goinfre/zmakhkha/venv/lib/python3.9/site-packages/rest_framework/views.py", line 253, in get_format_suffix
    if self.settings.FORMAT_SUFFIX_KWARG:
AttributeError: 'function' object has no attribute 'FORMAT_SUFFIX_KWARG'

During handling of the above exception, another exception occurred:

Traceback (most recent call last):
  File "/goinfre/zmakhkha/venv/lib/python3.9/site-packages/django/core/handlers/exception.py", line 55, in inner
    response = get_response(request)
  File "/goinfre/zmakhkha/venv/lib/python3.9/site-packages/django/core/handlers/base.py", line 197, in _get_response
    response = wrapped_callback(request, *callback_args, **callback_kwargs)
  File "/goinfre/zmakhkha/venv/lib/python3.9/site-packages/django/views/decorators/csrf.py", line 56, in wrapper_view
    return view_func(*args, **kwargs)
  File "/goinfre/zmakhkha/venv/lib/python3.9/site-packages/rest_framework/viewsets.py", line 124, in view
    return self.dispatch(request, *args, **kwargs)
  File "/goinfre/zmakhkha/venv/lib/python3.9/site-packages/rest_framework/views.py", line 509, in dispatch
    response = self.handle_exception(exc)
  File "/goinfre/zmakhkha/venv/lib/python3.9/site-packages/rest_framework/views.py", line 463, in handle_exception
    exception_handler = self.get_exception_handler()
  File "/goinfre/zmakhkha/venv/lib/python3.9/site-packages/rest_framework/views.py", line 298, in get_exception_handler
    return self.settings.EXCEPTION_HANDLER
AttributeError: 'function' object has no attribute 'EXCEPTION_HANDLER'
2024-08-03 09:27:30,011: ERROR: Internal Server Error: /users/
Traceback (most recent call last):
  File "/goinfre/zmakhkha/venv/lib/python3.9/site-packages/rest_framework/views.py", line 497, in dispatch
    self.initial(request, *args, **kwargs)
  File "/goinfre/zmakhkha/venv/lib/python3.9/site-packages/rest_framework/views.py", line 403, in initial
    self.format_kwarg = self.get_format_suffix(**kwargs)
  File "/goinfre/zmakhkha/venv/lib/python3.9/site-packages/rest_framework/views.py", line 253, in get_format_suffix
    if self.settings.FORMAT_SUFFIX_KWARG:
AttributeError: 'function' object has no attribute 'FORMAT_SUFFIX_KWARG'

During handling of the above exception, another exception occurred:

Traceback (most recent call last):
  File "/goinfre/zmakhkha/venv/lib/python3.9/site-packages/django/core/handlers/exception.py", line 55, in inner
    response = get_response(request)
  File "/goinfre/zmakhkha/venv/lib/python3.9/site-packages/django/core/handlers/base.py", line 197, in _get_response
    response = wrapped_callback(request, *callback_args, **callback_kwargs)
  File "/goinfre/zmakhkha/venv/lib/python3.9/site-packages/django/views/decorators/csrf.py", line 56, in wrapper_view
    return view_func(*args, **kwargs)
  File "/goinfre/zmakhkha/venv/lib/python3.9/site-packages/rest_framework/viewsets.py", line 124, in view
    return self.dispatch(request, *args, **kwargs)
  File "/goinfre/zmakhkha/venv/lib/python3.9/site-packages/rest_framework/views.py", line 509, in dispatch
    response = self.handle_exception(exc)
  File "/goinfre/zmakhkha/venv/lib/python3.9/site-packages/rest_framework/views.py", line 463, in handle_exception
    exception_handler = self.get_exception_handler()
  File "/goinfre/zmakhkha/venv/lib/python3.9/site-packages/rest_framework/views.py", line 298, in get_exception_handler
    return self.settings.EXCEPTION_HANDLER
AttributeError: 'function' object has no attribute 'EXCEPTION_HANDLER'
2024-08-03 09:28:08,466: ERROR: Internal Server Error: /users/
Traceback (most recent call last):
  File "/goinfre/zmakhkha/venv/lib/python3.9/site-packages/rest_framework/views.py", line 497, in dispatch
    self.initial(request, *args, **kwargs)
  File "/goinfre/zmakhkha/venv/lib/python3.9/site-packages/rest_framework/views.py", line 403, in initial
    self.format_kwarg = self.get_format_suffix(**kwargs)
  File "/goinfre/zmakhkha/venv/lib/python3.9/site-packages/rest_framework/views.py", line 253, in get_format_suffix
    if self.settings.FORMAT_SUFFIX_KWARG:
AttributeError: 'function' object has no attribute 'FORMAT_SUFFIX_KWARG'

During handling of the above exception, another exception occurred:

Traceback (most recent call last):
  File "/goinfre/zmakhkha/venv/lib/python3.9/site-packages/django/core/handlers/exception.py", line 55, in inner
    response = get_response(request)
  File "/goinfre/zmakhkha/venv/lib/python3.9/site-packages/django/core/handlers/base.py", line 197, in _get_response
    response = wrapped_callback(request, *callback_args, **callback_kwargs)
  File "/goinfre/zmakhkha/venv/lib/python3.9/site-packages/django/views/decorators/csrf.py", line 56, in wrapper_view
    return view_func(*args, **kwargs)
  File "/goinfre/zmakhkha/venv/lib/python3.9/site-packages/rest_framework/viewsets.py", line 124, in view
    return self.dispatch(request, *args, **kwargs)
  File "/goinfre/zmakhkha/venv/lib/python3.9/site-packages/rest_framework/views.py", line 509, in dispatch
    response = self.handle_exception(exc)
  File "/goinfre/zmakhkha/venv/lib/python3.9/site-packages/rest_framework/views.py", line 463, in handle_exception
    exception_handler = self.get_exception_handler()
  File "/goinfre/zmakhkha/venv/lib/python3.9/site-packages/rest_framework/views.py", line 298, in get_exception_handler
    return self.settings.EXCEPTION_HANDLER
AttributeError: 'function' object has no attribute 'EXCEPTION_HANDLER'
2024-08-03 09:28:08,631: INFO: /Users/zmakhkha/Desktop/promote-me/back/usrinfo/views.py changed, reloading.
2024-08-03 09:28:40,752: INFO: /Users/zmakhkha/Desktop/promote-me/back/usrinfo/views.py changed, reloading.
2024-08-03 09:28:42,865: ERROR: Internal Server Error: /users/
Traceback (most recent call last):
  File "/goinfre/zmakhkha/venv/lib/python3.9/site-packages/rest_framework/views.py", line 497, in dispatch
    self.initial(request, *args, **kwargs)
  File "/goinfre/zmakhkha/venv/lib/python3.9/site-packages/rest_framework/views.py", line 403, in initial
    self.format_kwarg = self.get_format_suffix(**kwargs)
  File "/goinfre/zmakhkha/venv/lib/python3.9/site-packages/rest_framework/views.py", line 253, in get_format_suffix
    if self.settings.FORMAT_SUFFIX_KWARG:
AttributeError: 'function' object has no attribute 'FORMAT_SUFFIX_KWARG'

During handling of the above exception, another exception occurred:

Traceback (most recent call last):
  File "/goinfre/zmakhkha/venv/lib/python3.9/site-packages/django/core/handlers/exception.py", line 55, in inner
    response = get_response(request)
  File "/goinfre/zmakhkha/venv/lib/python3.9/site-packages/django/core/handlers/base.py", line 197, in _get_response
    response = wrapped_callback(request, *callback_args, **callback_kwargs)
  File "/goinfre/zmakhkha/venv/lib/python3.9/site-packages/django/views/decorators/csrf.py", line 56, in wrapper_view
    return view_func(*args, **kwargs)
  File "/goinfre/zmakhkha/venv/lib/python3.9/site-packages/rest_framework/viewsets.py", line 124, in view
    return self.dispatch(request, *args, **kwargs)
  File "/goinfre/zmakhkha/venv/lib/python3.9/site-packages/rest_framework/views.py", line 509, in dispatch
    response = self.handle_exception(exc)
  File "/goinfre/zmakhkha/venv/lib/python3.9/site-packages/rest_framework/views.py", line 463, in handle_exception
    exception_handler = self.get_exception_handler()
  File "/goinfre/zmakhkha/venv/lib/python3.9/site-packages/rest_framework/views.py", line 298, in get_exception_handler
    return self.settings.EXCEPTION_HANDLER
AttributeError: 'function' object has no attribute 'EXCEPTION_HANDLER'
2024-08-03 09:29:17,405: WARNING: Not Found: /users//settings
2024-08-03 09:29:24,751: ERROR: Internal Server Error: /users/settings/
Traceback (most recent call last):
  File "/goinfre/zmakhkha/venv/lib/python3.9/site-packages/rest_framework/views.py", line 497, in dispatch
    self.initial(request, *args, **kwargs)
  File "/goinfre/zmakhkha/venv/lib/python3.9/site-packages/rest_framework/views.py", line 403, in initial
    self.format_kwarg = self.get_format_suffix(**kwargs)
  File "/goinfre/zmakhkha/venv/lib/python3.9/site-packages/rest_framework/views.py", line 253, in get_format_suffix
    if self.settings.FORMAT_SUFFIX_KWARG:
AttributeError: 'function' object has no attribute 'FORMAT_SUFFIX_KWARG'

During handling of the above exception, another exception occurred:

Traceback (most recent call last):
  File "/goinfre/zmakhkha/venv/lib/python3.9/site-packages/django/core/handlers/exception.py", line 55, in inner
    response = get_response(request)
  File "/goinfre/zmakhkha/venv/lib/python3.9/site-packages/django/core/handlers/base.py", line 197, in _get_response
    response = wrapped_callback(request, *callback_args, **callback_kwargs)
  File "/goinfre/zmakhkha/venv/lib/python3.9/site-packages/django/views/decorators/csrf.py", line 56, in wrapper_view
    return view_func(*args, **kwargs)
  File "/goinfre/zmakhkha/venv/lib/python3.9/site-packages/rest_framework/viewsets.py", line 124, in view
    return self.dispatch(request, *args, **kwargs)
  File "/goinfre/zmakhkha/venv/lib/python3.9/site-packages/rest_framework/views.py", line 509, in dispatch
    response = self.handle_exception(exc)
  File "/goinfre/zmakhkha/venv/lib/python3.9/site-packages/rest_framework/views.py", line 463, in handle_exception
    exception_handler = self.get_exception_handler()
  File "/goinfre/zmakhkha/venv/lib/python3.9/site-packages/rest_framework/views.py", line 298, in get_exception_handler
    return self.settings.EXCEPTION_HANDLER
AttributeError: 'function' object has no attribute 'EXCEPTION_HANDLER'
2024-08-03 09:30:56,957: INFO: /Users/zmakhkha/Desktop/promote-me/back/usrinfo/views.py changed, reloading.
2024-08-03 09:31:00,064: ERROR: Internal Server Error: /users/settings/
Traceback (most recent call last):
  File "/goinfre/zmakhkha/venv/lib/python3.9/site-packages/rest_framework/views.py", line 497, in dispatch
    self.initial(request, *args, **kwargs)
  File "/goinfre/zmakhkha/venv/lib/python3.9/site-packages/rest_framework/views.py", line 403, in initial
    self.format_kwarg = self.get_format_suffix(**kwargs)
  File "/goinfre/zmakhkha/venv/lib/python3.9/site-packages/rest_framework/views.py", line 253, in get_format_suffix
    if self.settings.FORMAT_SUFFIX_KWARG:
AttributeError: 'function' object has no attribute 'FORMAT_SUFFIX_KWARG'

During handling of the above exception, another exception occurred:

Traceback (most recent call last):
  File "/goinfre/zmakhkha/venv/lib/python3.9/site-packages/django/core/handlers/exception.py", line 55, in inner
    response = get_response(request)
  File "/goinfre/zmakhkha/venv/lib/python3.9/site-packages/django/core/handlers/base.py", line 197, in _get_response
    response = wrapped_callback(request, *callback_args, **callback_kwargs)
  File "/goinfre/zmakhkha/venv/lib/python3.9/site-packages/django/views/decorators/csrf.py", line 56, in wrapper_view
    return view_func(*args, **kwargs)
  File "/goinfre/zmakhkha/venv/lib/python3.9/site-packages/rest_framework/viewsets.py", line 124, in view
    return self.dispatch(request, *args, **kwargs)
  File "/goinfre/zmakhkha/venv/lib/python3.9/site-packages/rest_framework/views.py", line 509, in dispatch
    response = self.handle_exception(exc)
  File "/goinfre/zmakhkha/venv/lib/python3.9/site-packages/rest_framework/views.py", line 463, in handle_exception
    exception_handler = self.get_exception_handler()
  File "/goinfre/zmakhkha/venv/lib/python3.9/site-packages/rest_framework/views.py", line 298, in get_exception_handler
    return self.settings.EXCEPTION_HANDLER
AttributeError: 'function' object has no attribute 'EXCEPTION_HANDLER'
2024-08-03 09:31:01,107: ERROR: Internal Server Error: /users/settings/
Traceback (most recent call last):
  File "/goinfre/zmakhkha/venv/lib/python3.9/site-packages/rest_framework/views.py", line 497, in dispatch
    self.initial(request, *args, **kwargs)
  File "/goinfre/zmakhkha/venv/lib/python3.9/site-packages/rest_framework/views.py", line 403, in initial
    self.format_kwarg = self.get_format_suffix(**kwargs)
  File "/goinfre/zmakhkha/venv/lib/python3.9/site-packages/rest_framework/views.py", line 253, in get_format_suffix
    if self.settings.FORMAT_SUFFIX_KWARG:
AttributeError: 'function' object has no attribute 'FORMAT_SUFFIX_KWARG'

During handling of the above exception, another exception occurred:

Traceback (most recent call last):
  File "/goinfre/zmakhkha/venv/lib/python3.9/site-packages/django/core/handlers/exception.py", line 55, in inner
    response = get_response(request)
  File "/goinfre/zmakhkha/venv/lib/python3.9/site-packages/django/core/handlers/base.py", line 197, in _get_response
    response = wrapped_callback(request, *callback_args, **callback_kwargs)
  File "/goinfre/zmakhkha/venv/lib/python3.9/site-packages/django/views/decorators/csrf.py", line 56, in wrapper_view
    return view_func(*args, **kwargs)
  File "/goinfre/zmakhkha/venv/lib/python3.9/site-packages/rest_framework/viewsets.py", line 124, in view
    return self.dispatch(request, *args, **kwargs)
  File "/goinfre/zmakhkha/venv/lib/python3.9/site-packages/rest_framework/views.py", line 509, in dispatch
    response = self.handle_exception(exc)
  File "/goinfre/zmakhkha/venv/lib/python3.9/site-packages/rest_framework/views.py", line 463, in handle_exception
    exception_handler = self.get_exception_handler()
  File "/goinfre/zmakhkha/venv/lib/python3.9/site-packages/rest_framework/views.py", line 298, in get_exception_handler
    return self.settings.EXCEPTION_HANDLER
AttributeError: 'function' object has no attribute 'EXCEPTION_HANDLER'
2024-08-03 09:31:01,619: ERROR: Internal Server Error: /users/settings/
Traceback (most recent call last):
  File "/goinfre/zmakhkha/venv/lib/python3.9/site-packages/rest_framework/views.py", line 497, in dispatch
    self.initial(request, *args, **kwargs)
  File "/goinfre/zmakhkha/venv/lib/python3.9/site-packages/rest_framework/views.py", line 403, in initial
    self.format_kwarg = self.get_format_suffix(**kwargs)
  File "/goinfre/zmakhkha/venv/lib/python3.9/site-packages/rest_framework/views.py", line 253, in get_format_suffix
    if self.settings.FORMAT_SUFFIX_KWARG:
AttributeError: 'function' object has no attribute 'FORMAT_SUFFIX_KWARG'

During handling of the above exception, another exception occurred:

Traceback (most recent call last):
  File "/goinfre/zmakhkha/venv/lib/python3.9/site-packages/django/core/handlers/exception.py", line 55, in inner
    response = get_response(request)
  File "/goinfre/zmakhkha/venv/lib/python3.9/site-packages/django/core/handlers/base.py", line 197, in _get_response
    response = wrapped_callback(request, *callback_args, **callback_kwargs)
  File "/goinfre/zmakhkha/venv/lib/python3.9/site-packages/django/views/decorators/csrf.py", line 56, in wrapper_view
    return view_func(*args, **kwargs)
  File "/goinfre/zmakhkha/venv/lib/python3.9/site-packages/rest_framework/viewsets.py", line 124, in view
    return self.dispatch(request, *args, **kwargs)
  File "/goinfre/zmakhkha/venv/lib/python3.9/site-packages/rest_framework/views.py", line 509, in dispatch
    response = self.handle_exception(exc)
  File "/goinfre/zmakhkha/venv/lib/python3.9/site-packages/rest_framework/views.py", line 463, in handle_exception
    exception_handler = self.get_exception_handler()
  File "/goinfre/zmakhkha/venv/lib/python3.9/site-packages/rest_framework/views.py", line 298, in get_exception_handler
    return self.settings.EXCEPTION_HANDLER
AttributeError: 'function' object has no attribute 'EXCEPTION_HANDLER'
2024-08-03 09:31:02,171: ERROR: Internal Server Error: /users/settings/
Traceback (most recent call last):
  File "/goinfre/zmakhkha/venv/lib/python3.9/site-packages/rest_framework/views.py", line 497, in dispatch
    self.initial(request, *args, **kwargs)
  File "/goinfre/zmakhkha/venv/lib/python3.9/site-packages/rest_framework/views.py", line 403, in initial
    self.format_kwarg = self.get_format_suffix(**kwargs)
  File "/goinfre/zmakhkha/venv/lib/python3.9/site-packages/rest_framework/views.py", line 253, in get_format_suffix
    if self.settings.FORMAT_SUFFIX_KWARG:
AttributeError: 'function' object has no attribute 'FORMAT_SUFFIX_KWARG'

During handling of the above exception, another exception occurred:

Traceback (most recent call last):
  File "/goinfre/zmakhkha/venv/lib/python3.9/site-packages/django/core/handlers/exception.py", line 55, in inner
    response = get_response(request)
  File "/goinfre/zmakhkha/venv/lib/python3.9/site-packages/django/core/handlers/base.py", line 197, in _get_response
    response = wrapped_callback(request, *callback_args, **callback_kwargs)
  File "/goinfre/zmakhkha/venv/lib/python3.9/site-packages/django/views/decorators/csrf.py", line 56, in wrapper_view
    return view_func(*args, **kwargs)
  File "/goinfre/zmakhkha/venv/lib/python3.9/site-packages/rest_framework/viewsets.py", line 124, in view
    return self.dispatch(request, *args, **kwargs)
  File "/goinfre/zmakhkha/venv/lib/python3.9/site-packages/rest_framework/views.py", line 509, in dispatch
    response = self.handle_exception(exc)
  File "/goinfre/zmakhkha/venv/lib/python3.9/site-packages/rest_framework/views.py", line 463, in handle_exception
    exception_handler = self.get_exception_handler()
  File "/goinfre/zmakhkha/venv/lib/python3.9/site-packages/rest_framework/views.py", line 298, in get_exception_handler
    return self.settings.EXCEPTION_HANDLER
AttributeError: 'function' object has no attribute 'EXCEPTION_HANDLER'
2024-08-03 09:31:50,668: INFO: /Users/zmakhkha/Desktop/promote-me/back/usrinfo/views.py changed, reloading.
2024-08-03 09:32:14,240: ERROR: Internal Server Error: /users/settings/
Traceback (most recent call last):
  File "/goinfre/zmakhkha/venv/lib/python3.9/site-packages/rest_framework/views.py", line 497, in dispatch
    self.initial(request, *args, **kwargs)
  File "/goinfre/zmakhkha/venv/lib/python3.9/site-packages/rest_framework/views.py", line 403, in initial
    self.format_kwarg = self.get_format_suffix(**kwargs)
  File "/goinfre/zmakhkha/venv/lib/python3.9/site-packages/rest_framework/views.py", line 253, in get_format_suffix
    if self.settings.FORMAT_SUFFIX_KWARG:
AttributeError: 'function' object has no attribute 'FORMAT_SUFFIX_KWARG'

During handling of the above exception, another exception occurred:

Traceback (most recent call last):
  File "/goinfre/zmakhkha/venv/lib/python3.9/site-packages/django/core/handlers/exception.py", line 55, in inner
    response = get_response(request)
  File "/goinfre/zmakhkha/venv/lib/python3.9/site-packages/django/core/handlers/base.py", line 197, in _get_response
    response = wrapped_callback(request, *callback_args, **callback_kwargs)
  File "/goinfre/zmakhkha/venv/lib/python3.9/site-packages/django/views/decorators/csrf.py", line 56, in wrapper_view
    return view_func(*args, **kwargs)
  File "/goinfre/zmakhkha/venv/lib/python3.9/site-packages/rest_framework/viewsets.py", line 124, in view
    return self.dispatch(request, *args, **kwargs)
  File "/goinfre/zmakhkha/venv/lib/python3.9/site-packages/rest_framework/views.py", line 509, in dispatch
    response = self.handle_exception(exc)
  File "/goinfre/zmakhkha/venv/lib/python3.9/site-packages/rest_framework/views.py", line 463, in handle_exception
    exception_handler = self.get_exception_handler()
  File "/goinfre/zmakhkha/venv/lib/python3.9/site-packages/rest_framework/views.py", line 298, in get_exception_handler
    return self.settings.EXCEPTION_HANDLER
AttributeError: 'function' object has no attribute 'EXCEPTION_HANDLER'
2024-08-03 09:32:15,392: ERROR: Internal Server Error: /users/settings/
Traceback (most recent call last):
  File "/goinfre/zmakhkha/venv/lib/python3.9/site-packages/rest_framework/views.py", line 497, in dispatch
    self.initial(request, *args, **kwargs)
  File "/goinfre/zmakhkha/venv/lib/python3.9/site-packages/rest_framework/views.py", line 403, in initial
    self.format_kwarg = self.get_format_suffix(**kwargs)
  File "/goinfre/zmakhkha/venv/lib/python3.9/site-packages/rest_framework/views.py", line 253, in get_format_suffix
    if self.settings.FORMAT_SUFFIX_KWARG:
AttributeError: 'function' object has no attribute 'FORMAT_SUFFIX_KWARG'

During handling of the above exception, another exception occurred:

Traceback (most recent call last):
  File "/goinfre/zmakhkha/venv/lib/python3.9/site-packages/django/core/handlers/exception.py", line 55, in inner
    response = get_response(request)
  File "/goinfre/zmakhkha/venv/lib/python3.9/site-packages/django/core/handlers/base.py", line 197, in _get_response
    response = wrapped_callback(request, *callback_args, **callback_kwargs)
  File "/goinfre/zmakhkha/venv/lib/python3.9/site-packages/django/views/decorators/csrf.py", line 56, in wrapper_view
    return view_func(*args, **kwargs)
  File "/goinfre/zmakhkha/venv/lib/python3.9/site-packages/rest_framework/viewsets.py", line 124, in view
    return self.dispatch(request, *args, **kwargs)
  File "/goinfre/zmakhkha/venv/lib/python3.9/site-packages/rest_framework/views.py", line 509, in dispatch
    response = self.handle_exception(exc)
  File "/goinfre/zmakhkha/venv/lib/python3.9/site-packages/rest_framework/views.py", line 463, in handle_exception
    exception_handler = self.get_exception_handler()
  File "/goinfre/zmakhkha/venv/lib/python3.9/site-packages/rest_framework/views.py", line 298, in get_exception_handler
    return self.settings.EXCEPTION_HANDLER
AttributeError: 'function' object has no attribute 'EXCEPTION_HANDLER'
2024-08-03 09:32:15,988: ERROR: Internal Server Error: /users/settings/
Traceback (most recent call last):
  File "/goinfre/zmakhkha/venv/lib/python3.9/site-packages/rest_framework/views.py", line 497, in dispatch
    self.initial(request, *args, **kwargs)
  File "/goinfre/zmakhkha/venv/lib/python3.9/site-packages/rest_framework/views.py", line 403, in initial
    self.format_kwarg = self.get_format_suffix(**kwargs)
  File "/goinfre/zmakhkha/venv/lib/python3.9/site-packages/rest_framework/views.py", line 253, in get_format_suffix
    if self.settings.FORMAT_SUFFIX_KWARG:
AttributeError: 'function' object has no attribute 'FORMAT_SUFFIX_KWARG'

During handling of the above exception, another exception occurred:

Traceback (most recent call last):
  File "/goinfre/zmakhkha/venv/lib/python3.9/site-packages/django/core/handlers/exception.py", line 55, in inner
    response = get_response(request)
  File "/goinfre/zmakhkha/venv/lib/python3.9/site-packages/django/core/handlers/base.py", line 197, in _get_response
    response = wrapped_callback(request, *callback_args, **callback_kwargs)
  File "/goinfre/zmakhkha/venv/lib/python3.9/site-packages/django/views/decorators/csrf.py", line 56, in wrapper_view
    return view_func(*args, **kwargs)
  File "/goinfre/zmakhkha/venv/lib/python3.9/site-packages/rest_framework/viewsets.py", line 124, in view
    return self.dispatch(request, *args, **kwargs)
  File "/goinfre/zmakhkha/venv/lib/python3.9/site-packages/rest_framework/views.py", line 509, in dispatch
    response = self.handle_exception(exc)
  File "/goinfre/zmakhkha/venv/lib/python3.9/site-packages/rest_framework/views.py", line 463, in handle_exception
    exception_handler = self.get_exception_handler()
  File "/goinfre/zmakhkha/venv/lib/python3.9/site-packages/rest_framework/views.py", line 298, in get_exception_handler
    return self.settings.EXCEPTION_HANDLER
AttributeError: 'function' object has no attribute 'EXCEPTION_HANDLER'
2024-08-03 09:32:16,634: ERROR: Internal Server Error: /users/settings/
Traceback (most recent call last):
  File "/goinfre/zmakhkha/venv/lib/python3.9/site-packages/rest_framework/views.py", line 497, in dispatch
    self.initial(request, *args, **kwargs)
  File "/goinfre/zmakhkha/venv/lib/python3.9/site-packages/rest_framework/views.py", line 403, in initial
    self.format_kwarg = self.get_format_suffix(**kwargs)
  File "/goinfre/zmakhkha/venv/lib/python3.9/site-packages/rest_framework/views.py", line 253, in get_format_suffix
    if self.settings.FORMAT_SUFFIX_KWARG:
AttributeError: 'function' object has no attribute 'FORMAT_SUFFIX_KWARG'

During handling of the above exception, another exception occurred:

Traceback (most recent call last):
  File "/goinfre/zmakhkha/venv/lib/python3.9/site-packages/django/core/handlers/exception.py", line 55, in inner
    response = get_response(request)
  File "/goinfre/zmakhkha/venv/lib/python3.9/site-packages/django/core/handlers/base.py", line 197, in _get_response
    response = wrapped_callback(request, *callback_args, **callback_kwargs)
  File "/goinfre/zmakhkha/venv/lib/python3.9/site-packages/django/views/decorators/csrf.py", line 56, in wrapper_view
    return view_func(*args, **kwargs)
  File "/goinfre/zmakhkha/venv/lib/python3.9/site-packages/rest_framework/viewsets.py", line 124, in view
    return self.dispatch(request, *args, **kwargs)
  File "/goinfre/zmakhkha/venv/lib/python3.9/site-packages/rest_framework/views.py", line 509, in dispatch
    response = self.handle_exception(exc)
  File "/goinfre/zmakhkha/venv/lib/python3.9/site-packages/rest_framework/views.py", line 463, in handle_exception
    exception_handler = self.get_exception_handler()
  File "/goinfre/zmakhkha/venv/lib/python3.9/site-packages/rest_framework/views.py", line 298, in get_exception_handler
    return self.settings.EXCEPTION_HANDLER
AttributeError: 'function' object has no attribute 'EXCEPTION_HANDLER'
2024-08-03 09:32:17,112: ERROR: Internal Server Error: /users/settings/
Traceback (most recent call last):
  File "/goinfre/zmakhkha/venv/lib/python3.9/site-packages/rest_framework/views.py", line 497, in dispatch
    self.initial(request, *args, **kwargs)
  File "/goinfre/zmakhkha/venv/lib/python3.9/site-packages/rest_framework/views.py", line 403, in initial
    self.format_kwarg = self.get_format_suffix(**kwargs)
  File "/goinfre/zmakhkha/venv/lib/python3.9/site-packages/rest_framework/views.py", line 253, in get_format_suffix
    if self.settings.FORMAT_SUFFIX_KWARG:
AttributeError: 'function' object has no attribute 'FORMAT_SUFFIX_KWARG'

During handling of the above exception, another exception occurred:

Traceback (most recent call last):
  File "/goinfre/zmakhkha/venv/lib/python3.9/site-packages/django/core/handlers/exception.py", line 55, in inner
    response = get_response(request)
  File "/goinfre/zmakhkha/venv/lib/python3.9/site-packages/django/core/handlers/base.py", line 197, in _get_response
    response = wrapped_callback(request, *callback_args, **callback_kwargs)
  File "/goinfre/zmakhkha/venv/lib/python3.9/site-packages/django/views/decorators/csrf.py", line 56, in wrapper_view
    return view_func(*args, **kwargs)
  File "/goinfre/zmakhkha/venv/lib/python3.9/site-packages/rest_framework/viewsets.py", line 124, in view
    return self.dispatch(request, *args, **kwargs)
  File "/goinfre/zmakhkha/venv/lib/python3.9/site-packages/rest_framework/views.py", line 509, in dispatch
    response = self.handle_exception(exc)
  File "/goinfre/zmakhkha/venv/lib/python3.9/site-packages/rest_framework/views.py", line 463, in handle_exception
    exception_handler = self.get_exception_handler()
  File "/goinfre/zmakhkha/venv/lib/python3.9/site-packages/rest_framework/views.py", line 298, in get_exception_handler
    return self.settings.EXCEPTION_HANDLER
AttributeError: 'function' object has no attribute 'EXCEPTION_HANDLER'
2024-08-03 09:32:23,120: INFO: /Users/zmakhkha/Desktop/promote-me/back/usrinfo/views.py changed, reloading.
2024-08-03 09:32:45,015: INFO: /Users/zmakhkha/Desktop/promote-me/back/usrinfo/views.py changed, reloading.
2024-08-03 09:32:59,206: INFO: /Users/zmakhkha/Desktop/promote-me/back/usrinfo/views.py changed, reloading.
2024-08-03 09:33:03,767: INFO: /Users/zmakhkha/Desktop/promote-me/back/usrinfo/views.py changed, reloading.
2024-08-03 09:33:07,312: INFO: /Users/zmakhkha/Desktop/promote-me/back/usrinfo/views.py changed, reloading.
2024-08-03 09:33:08,581: WARNING: Not Found: /users/settings/
2024-08-03 09:33:39,383: INFO: /Users/zmakhkha/Desktop/promote-me/back/usrinfo/views.py changed, reloading.
2024-08-03 09:33:53,111: INFO: /Users/zmakhkha/Desktop/promote-me/back/usrinfo/views.py changed, reloading.
2024-08-03 09:36:27,463: INFO: /Users/zmakhkha/Desktop/promote-me/back/usrinfo/serializers.py changed, reloading.
2024-08-03 09:36:30,213: INFO: /Users/zmakhkha/Desktop/promote-me/back/usrinfo/serializers.py changed, reloading.
2024-08-03 09:37:36,795: WARNING: Forbidden: /users/setting/
2024-08-03 09:38:32,601: WARNING: Not Found: /auth/signIp/
2024-08-03 09:38:39,005: WARNING: Not Found: /auth/signIp/
2024-08-03 09:38:49,528: WARNING: Method Not Allowed: /auth/signIn/
2024-08-03 09:39:34,531: WARNING: Not Found: /auth/signIp/
2024-08-03 09:39:44,248: INFO: [AuthViewSet::signIn] User lexi@mail.com logged in successfully
2024-08-03 09:40:17,898: WARNING: Forbidden: /users/setting/
2024-08-03 09:42:52,048: INFO: /Users/zmakhkha/Desktop/promote-me/back/core/settings.py changed, reloading.
2024-08-03 09:43:03,959: WARNING: Forbidden: /users/setting/
2024-08-03 09:43:17,201: WARNING: Forbidden: /users/setting/
2024-08-03 09:43:30,198: WARNING: Forbidden: /users/
2024-08-03 09:44:16,729: WARNING: Forbidden: /users/
2024-08-03 09:44:18,522: WARNING: Forbidden: /users/
2024-08-03 09:44:19,465: WARNING: Forbidden: /users/
2024-08-03 10:06:39,787: WARNING: Forbidden: /users/
2024-08-03 10:06:41,330: WARNING: Forbidden: /users/
2024-08-03 10:06:51,872: WARNING: Forbidden: /users/
2024-08-03 10:08:04,225: ERROR: Internal Server Error: /users
Traceback (most recent call last):
  File "/goinfre/zmakhkha/venv/lib/python3.9/site-packages/django/core/handlers/exception.py", line 55, in inner
    response = get_response(request)
  File "/goinfre/zmakhkha/venv/lib/python3.9/site-packages/django/utils/deprecation.py", line 136, in __call__
    response = self.process_response(request, response)
  File "/goinfre/zmakhkha/venv/lib/python3.9/site-packages/django/middleware/common.py", line 108, in process_response
    return self.response_redirect_class(self.get_full_path_with_slash(request))
  File "/goinfre/zmakhkha/venv/lib/python3.9/site-packages/django/middleware/common.py", line 87, in get_full_path_with_slash
    raise RuntimeError(
RuntimeError: You called this URL via POST, but the URL doesn't end in a slash and you have APPEND_SLASH set. Django can't redirect to the slash URL while maintaining POST data. Change your form to point to localhost:2000/users/ (note the trailing slash), or set APPEND_SLASH=False in your Django settings.
2024-08-03 10:08:22,119: WARNING: Forbidden: /users/
2024-08-03 10:08:24,198: WARNING: Forbidden: /users/
2024-08-03 10:08:39,788: WARNING: Forbidden: /users/
2024-08-03 10:09:19,054: INFO: /Users/zmakhkha/Desktop/promote-me/back/core/settings.py changed, reloading.
2024-08-03 10:10:25,111: WARNING: Forbidden: /users/
2024-08-03 10:10:52,670: WARNING: Forbidden: /users/
2024-08-03 10:10:53,180: WARNING: Forbidden: /users/
2024-08-03 10:10:53,532: WARNING: Forbidden: /users/
2024-08-03 10:11:08,576: WARNING: Forbidden: /users/
2024-08-03 10:11:22,237: WARNING: Forbidden: /users/
2024-08-03 10:11:40,711: WARNING: Not Found: /users/settings/
2024-08-03 10:11:43,649: WARNING: Not Found: /users/settings/
2024-08-03 10:12:13,152: INFO: /Users/zmakhkha/Desktop/promote-me/back/usrinfo/views.py changed, reloading.
2024-08-03 10:13:18,735: WARNING: Forbidden: /tags/
2024-08-03 10:17:59,348: INFO: /Users/zmakhkha/Desktop/promote-me/back/core/settings.py changed, reloading.
2024-08-03 10:18:02,208: WARNING: Unauthorized: /tags/
2024-08-03 10:18:03,871: WARNING: Unauthorized: /tags/
2024-08-03 10:18:09,369: WARNING: Unauthorized: /tags/
2024-08-03 10:18:10,471: WARNING: Unauthorized: /tags/
2024-08-03 10:18:11,207: WARNING: Unauthorized: /tags/
2024-08-03 10:18:12,190: WARNING: Unauthorized: /tags/
2024-08-03 10:18:40,992: INFO: /Users/zmakhkha/Desktop/promote-me/back/core/settings.py changed, reloading.
2024-08-03 10:18:42,230: WARNING: Unauthorized: /tags/
2024-08-03 10:18:45,726: WARNING: Unauthorized: /tags/
2024-08-03 10:19:57,955: WARNING: Unauthorized: /users/signIn/
2024-08-03 10:20:26,253: WARNING: Not Found: /signIn/
2024-08-03 10:20:31,219: WARNING: Unauthorized: /tags/signIn/
2024-08-03 10:20:48,270: WARNING: Unauthorized: /auth/signIn/
2024-08-03 10:21:36,510: INFO: [AuthViewSet::signIn] User lexi@mail.com logged in successfully
2024-08-03 10:21:44,432: WARNING: Unauthorized: /tags/signIn/
2024-08-03 10:21:49,024: WARNING: Unauthorized: /tags/
2024-08-03 10:40:29,830: INFO: /Users/zmakhkha/Desktop/promote-me/back/usrinfo/views.py changed, reloading.
2024-08-03 10:40:43,795: INFO: /Users/zmakhkha/Desktop/promote-me/back/usrinfo/urls.py changed, reloading.
2024-08-03 10:40:50,401: INFO: /Users/zmakhkha/Desktop/promote-me/back/usrinfo/urls.py changed, reloading.
2024-08-03 10:40:52,952: INFO: /Users/zmakhkha/Desktop/promote-me/back/usrinfo/urls.py changed, reloading.
2024-08-03 10:41:01,559: INFO: /Users/zmakhkha/Desktop/promote-me/back/usrinfo/urls.py changed, reloading.
2024-08-03 10:41:23,452: INFO: /Users/zmakhkha/Desktop/promote-me/back/core/settings.py changed, reloading.
2024-08-03 10:42:58,210: WARNING: Not Found: /auth/user/
2024-08-03 10:42:59,869: WARNING: Unauthorized: /api/logout/
2024-08-03 10:43:01,316: WARNING: Unauthorized: /api/logout/
2024-08-03 10:43:03,995: WARNING: Unauthorized: /api/logout/
2024-08-03 10:44:35,308: WARNING: Unauthorized: /api/logout/
2024-08-03 10:45:02,039: INFO: /Users/zmakhkha/Desktop/promote-me/back/usrinfo/views.py changed, reloading.
